<?xml version="1.0" ?>
<!-- =================================================================================== -->
<!-- |    This document was autogenerated by xacro from cob3-8.urdf.xacro              | -->
<!-- |    EDITING THIS FILE BY HAND IS NOT RECOMMENDED                                 | -->
<!-- =================================================================================== -->
<robot name="cob3-8" xmlns:xacro="http://www.ros.org/wiki/xacro">
  <!-- common stuff -->
  <material name="IPA/LightGrey">
    <color rgba="0.7 0.7 0.7 1.0"/>
  </material>
  <material name="IPA/DarkGrey">
    <color rgba="0.4 0.4 0.4 1.0"/>
  </material>
  <material name="IPA/Orange">
    <color rgba="1.0 0.4 0.0 1.0"/>
  </material>
  <material name="IPA/Black">
    <color rgba="0.0 0.0 0.0 1.0"/>
  </material>
  <material name="IPA/Blue">
    <color rgba="0.0 0.0 0.5 1.0"/>
  </material>
  <material name="Schunk/LightGrey">
    <color rgba="0.7 0.7 0.7 1.0"/>
  </material>
  <material name="Schunk/DarkGrey">
    <color rgba="0.4 0.4 0.4 1.0"/>
  </material>
  <material name="Schunk/Black">
    <color rgba="0.0 0.0 0.0 1.0"/>
  </material>
  <material name="Schunk/DarkGolden">
    <color rgba="0.4 0.4 0.3 1.0"/>
  </material>
  <material name="Schunk/Blue">
    <color rgba="0.0 0.0 0.8 1.0"/>
  </material>
  <!-- calibration -->
  <!-- base -->
  <!-- tray -->
  <!-- torso -->
  <!-- head -->
  <!-- arm -->
  <!-- sdh -->
  <!-- generic simulator_gazebo plugins for starting mechanism control, ros time, ros battery -->
  <gazebo>
    <plugin filename="libgazebo_ros_control.so" name="ros_control">
      <!--robotNamespace>/</robotNamespace-->
      <!--robotSimType>gazebo_ros_control/DefaultRobotHWSim</robotSimType-->
    </plugin>
  </gazebo>
  <!-- composition of the robot -->
  <link name="base_link">
    <inertial>
      <mass value="116.0"/>
      <origin xyz="0 0 0"/>
      <inertia ixx="5.652232699207" ixy="-0.009719934438" ixz="1.293988226423" iyy="5.669473158652" iyz="-0.007379583694" izz="3.683196351726"/>
    </inertial>
    <visual>
      <origin rpy="0 0 0" xyz="0 0 0"/>
      <geometry>
        <mesh filename="package://cob_description/meshes/cob3_base/base.stl"/>
        <!--box size="${base_size_x} ${base_size_y} ${base_collision_size_z}" /-->
      </geometry>
      <material name="IPA/LightGrey"/>
    </visual>
    <collision>
      <origin rpy="0 0 0" xyz="0 0 0"/>
      <geometry>
        <mesh filename="package://cob_description/meshes/cob3_base/base_collision.stl"/>
        <!--box size="${base_size_x} ${base_size_y} ${base_collision_size_z}" /-->
      </geometry>
    </collision>
  </link>
  <link name="base_footprint"/>
  <joint name="base_footprint_joint" type="fixed">
    <origin rpy="0 0 0" xyz="0 0 0"/>
    <child link="base_link"/>
    <parent link="base_footprint"/>
  </joint>
  <joint name="base_laser_front_joint" type="fixed">
    <axis xyz="0 1 0"/>
    <origin rpy="3.1416 0.0 0.0" xyz="0.325 0.0 0.135"/>
    <parent link="base_link"/>
    <child link="base_laser_front_link"/>
  </joint>
  <link name="base_laser_front_link" type="laser">
    <inertial>
      <mass value="1.2"/>
      <origin rpy="0 0 0" xyz="0 0 0"/>
      <inertia ixx="0.0029999988" ixy="0.0" ixz="0.0" iyy="0.0029999988" iyz="0.0" izz="0.0015"/>
    </inertial>
    <visual>
      <origin rpy="0 0 0" xyz="0 0 0"/>
      <geometry>
        <mesh filename="package://cob_description/meshes/sensors/sick_s300_laser.dae"/>
        <!--box size="0.001 0.001 0.001" /-->
      </geometry>
      <material name="IPA/LightGrey"/>
    </visual>
    <collision>
      <origin rpy="0 0 0" xyz="0 0 0"/>
      <geometry>
        <cylinder length="0.15" radius="0.05"/>
      </geometry>
    </collision>
  </link>
  <gazebo reference="base_laser_front_link">
    <sensor name="base_laser_front" type="ray">
      <always_on>true</always_on>
      <update_rate>10</update_rate>
      <pose>0 0 0 0 0 0</pose>
      <visualize>false</visualize>
      <ray>
        <scan>
          <horizontal>
            <samples>541</samples>
            <resolution>1.0</resolution>
            <min_angle>-2.3562</min_angle>
            <max_angle>2.3562</max_angle>
          </horizontal>
        </scan>
        <range>
          <min>0.05</min>
          <max>30.0</max>
          <resolution>0.03</resolution>
        </range>
        <noise>
          <type>gaussian</type>
          <mean>0.0</mean>
          <stddev>0.005</stddev>
        </noise>
      </ray>
      <plugin filename="libgazebo_ros_laser.so" name="gazebo_ros_base_laser_front_controller">
        <topicName>scan_front_raw</topicName>
        <frameName>base_laser_front_link</frameName>
      </plugin>
    </sensor>
    <!--material value="IPA/LightGrey" /-->
  </gazebo>
  <joint name="base_laser_rear_joint" type="fixed">
    <axis xyz="0 1 0"/>
    <origin rpy="3.1416 0.0 3.1416" xyz="-0.325 0.0 0.135"/>
    <parent link="base_link"/>
    <child link="base_laser_rear_link"/>
  </joint>
  <link name="base_laser_rear_link" type="laser">
    <inertial>
      <mass value="1.2"/>
      <origin rpy="0 0 0" xyz="0 0 0"/>
      <inertia ixx="0.0029999988" ixy="0.0" ixz="0.0" iyy="0.0029999988" iyz="0.0" izz="0.0015"/>
    </inertial>
    <visual>
      <origin rpy="0 0 0" xyz="0 0 0"/>
      <geometry>
        <mesh filename="package://cob_description/meshes/sensors/sick_s300_laser.dae"/>
        <!--box size="0.001 0.001 0.001" /-->
      </geometry>
      <material name="IPA/LightGrey"/>
    </visual>
    <collision>
      <origin rpy="0 0 0" xyz="0 0 0"/>
      <geometry>
        <cylinder length="0.15" radius="0.05"/>
      </geometry>
    </collision>
  </link>
  <gazebo reference="base_laser_rear_link">
    <sensor name="base_laser_rear" type="ray">
      <always_on>true</always_on>
      <update_rate>10</update_rate>
      <pose>0 0 0 0 0 0</pose>
      <visualize>false</visualize>
      <ray>
        <scan>
          <horizontal>
            <samples>541</samples>
            <resolution>1.0</resolution>
            <min_angle>-2.3562</min_angle>
            <max_angle>2.3562</max_angle>
          </horizontal>
        </scan>
        <range>
          <min>0.05</min>
          <max>30.0</max>
          <resolution>0.03</resolution>
        </range>
        <noise>
          <type>gaussian</type>
          <mean>0.0</mean>
          <stddev>0.005</stddev>
        </noise>
      </ray>
      <plugin filename="libgazebo_ros_laser.so" name="gazebo_ros_base_laser_rear_controller">
        <topicName>scan_rear_raw</topicName>
        <frameName>base_laser_rear_link</frameName>
      </plugin>
    </sensor>
    <!--material value="IPA/LightGrey" /-->
  </gazebo>
  <joint name="base_laser_top_joint" type="fixed">
    <axis xyz="0 1 0"/>
    <origin rpy="0.0 0.0 0.0" xyz="-0.252 0.0 0.42"/>
    <parent link="base_link"/>
    <child link="base_laser_top_link"/>
  </joint>
  <link name="base_laser_top_link" type="laser"/>
  <gazebo reference="base_laser_top_link">
    <sensor name="base_laser_top" type="ray">
      <always_on>true</always_on>
      <update_rate>10</update_rate>
      <pose>0 0 0 0 0 0</pose>
      <visualize>false</visualize>
      <ray>
        <scan>
          <horizontal>
            <samples>640</samples>
            <resolution>1.0</resolution>
            <min_angle>-2.3562</min_angle>
            <max_angle>2.3562</max_angle>
          </horizontal>
        </scan>
        <range>
          <min>0.05</min>
          <max>10.0</max>
          <resolution>0.01</resolution>
        </range>
        <noise>
          <type>gaussian</type>
          <mean>0.0</mean>
          <stddev>0.005</stddev>
        </noise>
      </ray>
      <plugin filename="libgazebo_ros_laser.so" name="gazebo_ros_base_laser_top_controller">
        <topicName>scan_top_raw</topicName>
        <frameName>base_laser_top_link</frameName>
      </plugin>
    </sensor>
    <material>IPA/LightGrey</material>
  </gazebo>
  <joint name="fl_caster_rotation_joint" type="continuous">
    <axis xyz="0 0 1"/>
    <limit effort="100" velocity="100"/>
    <!-- alpha tested velocity and effort limits -->
    <safety_controller k_velocity="10"/>
    <calibration rising="-0.785398163397"/>
    <dynamics damping="0.0" friction="0.0"/>
    <origin rpy="0 0 0" xyz="0.235 0.185 0.075"/>
    <parent link="base_link"/>
    <child link="fl_caster_rotation_link"/>
  </joint>
  <link name="fl_caster_rotation_link">
    <inertial>
      <mass value="5.9"/>
      <origin xyz="0 0 0"/>
      <inertia ixx="0.04" ixy="-0.0007" ixz="0.0" iyy="0.02" iyz="-0.000004" izz="0.05"/>
    </inertial>
    <visual>
      <origin rpy="0 0 0" xyz="0 0 0"/>
      <geometry>
        <mesh filename="package://cob_description/meshes/cob3_base/caster.stl"/>
        <!--box size="0.001 0.001 0.001" /-->
      </geometry>
      <material name="IPA/LightGrey"/>
    </visual>
    <collision>
      <origin rpy="0 0 0" xyz="0 0 0"/>
      <geometry>
        <box size="0.001 0.001 0.001"/>
      </geometry>
    </collision>
  </link>
  <transmission name="fl_caster_rotation_trans">
    <type>transmission_interface/SimpleTransmission</type>
    <joint name="fl_caster_rotation_joint"/>
    <actuator name="fl_caster_rotation_motor">
      <hardwareInterface>EffortJointInterface</hardwareInterface>
      <mechanicalReduction>-79.2380952381</mechanicalReduction>
    </actuator>
  </transmission>
  <joint name="fl_caster_r_wheel_joint" type="continuous">
    <axis xyz="0 1 0"/>
    <limit effort="100" velocity="100"/>
    <!-- alpha tested effort and velocity limits -->
    <safety_controller k_velocity="10"/>
    <dynamics damping="0.0" friction="0.0"/>
    <origin rpy="0 0 0" xyz="0 -0.0 0"/>
    <parent link="fl_caster_rotation_link"/>
    <child link="fl_caster_r_wheel_link"/>
  </joint>
  <link name="fl_caster_r_wheel_link">
    <inertial>
      <mass value="0.44036"/>
      <origin xyz="0 0 0"/>
      <inertia ixx="0.012411765597" ixy="-0.000711733678" ixz="0.00050272983" iyy="0.015218160428" iyz="-0.000004273467" izz="0.011763977943"/>
    </inertial>
    <visual>
      <origin rpy="1.57079632679 0 0" xyz="0 0 0"/>
      <geometry>
        <cylinder length="0.034" radius="0.074792"/>
      </geometry>
      <material name="IPA/LightGrey"/>
    </visual>
    <collision>
      <origin rpy="1.57079632679 0 0" xyz="0 0 0"/>
      <!-- rotation because cyl. geom primitive has symmetry axis in +x direction -->
      <geometry>
        <cylinder length="0.034" radius="0.074792"/>
      </geometry>
    </collision>
  </link>
  <gazebo reference="fl_caster_r_wheel_link">
    <material value="IPA/LightGrey"/>
  </gazebo>
  <transmission name="fl_caster_r_wheel_trans">
    <type>transmission_interface/SimpleTransmission</type>
    <joint name="fl_caster_r_wheel_joint"/>
    <actuator name="fl_caster_r_wheel_motor">
      <hardwareInterface>EffortJointInterface</hardwareInterface>
      <mechanicalReduction>-79.2380952381</mechanicalReduction>
    </actuator>
  </transmission>
  <gazebo reference="fl_caster_rotation_link">
    <material value="IPA/Metal"/>
  </gazebo>
  <joint name="fr_caster_rotation_joint" type="continuous">
    <axis xyz="0 0 1"/>
    <limit effort="100" velocity="100"/>
    <!-- alpha tested velocity and effort limits -->
    <safety_controller k_velocity="10"/>
    <calibration rising="-0.785398163397"/>
    <dynamics damping="0.0" friction="0.0"/>
    <origin rpy="0 0 0" xyz="0.235 -0.185 0.075"/>
    <parent link="base_link"/>
    <child link="fr_caster_rotation_link"/>
  </joint>
  <link name="fr_caster_rotation_link">
    <inertial>
      <mass value="5.9"/>
      <origin xyz="0 0 0"/>
      <inertia ixx="0.04" ixy="-0.0007" ixz="0.0" iyy="0.02" iyz="-0.000004" izz="0.05"/>
    </inertial>
    <visual>
      <origin rpy="0 0 0" xyz="0 0 0"/>
      <geometry>
        <mesh filename="package://cob_description/meshes/cob3_base/caster.stl"/>
        <!--box size="0.001 0.001 0.001" /-->
      </geometry>
      <material name="IPA/LightGrey"/>
    </visual>
    <collision>
      <origin rpy="0 0 0" xyz="0 0 0"/>
      <geometry>
        <box size="0.001 0.001 0.001"/>
      </geometry>
    </collision>
  </link>
  <transmission name="fr_caster_rotation_trans">
    <type>transmission_interface/SimpleTransmission</type>
    <joint name="fr_caster_rotation_joint"/>
    <actuator name="fr_caster_rotation_motor">
      <hardwareInterface>EffortJointInterface</hardwareInterface>
      <mechanicalReduction>-79.2380952381</mechanicalReduction>
    </actuator>
  </transmission>
  <joint name="fr_caster_r_wheel_joint" type="continuous">
    <axis xyz="0 1 0"/>
    <limit effort="100" velocity="100"/>
    <!-- alpha tested effort and velocity limits -->
    <safety_controller k_velocity="10"/>
    <dynamics damping="0.0" friction="0.0"/>
    <origin rpy="0 0 0" xyz="0 -0.0 0"/>
    <parent link="fr_caster_rotation_link"/>
    <child link="fr_caster_r_wheel_link"/>
  </joint>
  <link name="fr_caster_r_wheel_link">
    <inertial>
      <mass value="0.44036"/>
      <origin xyz="0 0 0"/>
      <inertia ixx="0.012411765597" ixy="-0.000711733678" ixz="0.00050272983" iyy="0.015218160428" iyz="-0.000004273467" izz="0.011763977943"/>
    </inertial>
    <visual>
      <origin rpy="1.57079632679 0 0" xyz="0 0 0"/>
      <geometry>
        <cylinder length="0.034" radius="0.074792"/>
      </geometry>
      <material name="IPA/LightGrey"/>
    </visual>
    <collision>
      <origin rpy="1.57079632679 0 0" xyz="0 0 0"/>
      <!-- rotation because cyl. geom primitive has symmetry axis in +x direction -->
      <geometry>
        <cylinder length="0.034" radius="0.074792"/>
      </geometry>
    </collision>
  </link>
  <gazebo reference="fr_caster_r_wheel_link">
    <material value="IPA/LightGrey"/>
  </gazebo>
  <transmission name="fr_caster_r_wheel_trans">
    <type>transmission_interface/SimpleTransmission</type>
    <joint name="fr_caster_r_wheel_joint"/>
    <actuator name="fr_caster_r_wheel_motor">
      <hardwareInterface>EffortJointInterface</hardwareInterface>
      <mechanicalReduction>-79.2380952381</mechanicalReduction>
    </actuator>
  </transmission>
  <gazebo reference="fr_caster_rotation_link">
    <material value="IPA/Metal"/>
  </gazebo>
  <joint name="bl_caster_rotation_joint" type="continuous">
    <axis xyz="0 0 1"/>
    <limit effort="100" velocity="100"/>
    <!-- alpha tested velocity and effort limits -->
    <safety_controller k_velocity="10"/>
    <calibration rising="2.35619449019"/>
    <dynamics damping="0.0" friction="0.0"/>
    <origin rpy="0 0 0" xyz="-0.235 0.185 0.075"/>
    <parent link="base_link"/>
    <child link="bl_caster_rotation_link"/>
  </joint>
  <link name="bl_caster_rotation_link">
    <inertial>
      <mass value="5.9"/>
      <origin xyz="0 0 0"/>
      <inertia ixx="0.04" ixy="-0.0007" ixz="0.0" iyy="0.02" iyz="-0.000004" izz="0.05"/>
    </inertial>
    <visual>
      <origin rpy="0 0 0" xyz="0 0 0"/>
      <geometry>
        <mesh filename="package://cob_description/meshes/cob3_base/caster.stl"/>
        <!--box size="0.001 0.001 0.001" /-->
      </geometry>
      <material name="IPA/LightGrey"/>
    </visual>
    <collision>
      <origin rpy="0 0 0" xyz="0 0 0"/>
      <geometry>
        <box size="0.001 0.001 0.001"/>
      </geometry>
    </collision>
  </link>
  <transmission name="bl_caster_rotation_trans">
    <type>transmission_interface/SimpleTransmission</type>
    <joint name="bl_caster_rotation_joint"/>
    <actuator name="bl_caster_rotation_motor">
      <hardwareInterface>EffortJointInterface</hardwareInterface>
      <mechanicalReduction>-79.2380952381</mechanicalReduction>
    </actuator>
  </transmission>
  <joint name="bl_caster_r_wheel_joint" type="continuous">
    <axis xyz="0 1 0"/>
    <limit effort="100" velocity="100"/>
    <!-- alpha tested effort and velocity limits -->
    <safety_controller k_velocity="10"/>
    <dynamics damping="0.0" friction="0.0"/>
    <origin rpy="0 0 0" xyz="0 -0.0 0"/>
    <parent link="bl_caster_rotation_link"/>
    <child link="bl_caster_r_wheel_link"/>
  </joint>
  <link name="bl_caster_r_wheel_link">
    <inertial>
      <mass value="0.44036"/>
      <origin xyz="0 0 0"/>
      <inertia ixx="0.012411765597" ixy="-0.000711733678" ixz="0.00050272983" iyy="0.015218160428" iyz="-0.000004273467" izz="0.011763977943"/>
    </inertial>
    <visual>
      <origin rpy="1.57079632679 0 0" xyz="0 0 0"/>
      <geometry>
        <cylinder length="0.034" radius="0.074792"/>
      </geometry>
      <material name="IPA/LightGrey"/>
    </visual>
    <collision>
      <origin rpy="1.57079632679 0 0" xyz="0 0 0"/>
      <!-- rotation because cyl. geom primitive has symmetry axis in +x direction -->
      <geometry>
        <cylinder length="0.034" radius="0.074792"/>
      </geometry>
    </collision>
  </link>
  <gazebo reference="bl_caster_r_wheel_link">
    <material value="IPA/LightGrey"/>
  </gazebo>
  <transmission name="bl_caster_r_wheel_trans">
    <type>transmission_interface/SimpleTransmission</type>
    <joint name="bl_caster_r_wheel_joint"/>
    <actuator name="bl_caster_r_wheel_motor">
      <hardwareInterface>EffortJointInterface</hardwareInterface>
      <mechanicalReduction>-79.2380952381</mechanicalReduction>
    </actuator>
  </transmission>
  <gazebo reference="bl_caster_rotation_link">
    <material value="IPA/Metal"/>
  </gazebo>
  <joint name="br_caster_rotation_joint" type="continuous">
    <axis xyz="0 0 1"/>
    <limit effort="100" velocity="100"/>
    <!-- alpha tested velocity and effort limits -->
    <safety_controller k_velocity="10"/>
    <calibration rising="2.35619449019"/>
    <dynamics damping="0.0" friction="0.0"/>
    <origin rpy="0 0 0" xyz="-0.235 -0.185 0.075"/>
    <parent link="base_link"/>
    <child link="br_caster_rotation_link"/>
  </joint>
  <link name="br_caster_rotation_link">
    <inertial>
      <mass value="5.9"/>
      <origin xyz="0 0 0"/>
      <inertia ixx="0.04" ixy="-0.0007" ixz="0.0" iyy="0.02" iyz="-0.000004" izz="0.05"/>
    </inertial>
    <visual>
      <origin rpy="0 0 0" xyz="0 0 0"/>
      <geometry>
        <mesh filename="package://cob_description/meshes/cob3_base/caster.stl"/>
        <!--box size="0.001 0.001 0.001" /-->
      </geometry>
      <material name="IPA/LightGrey"/>
    </visual>
    <collision>
      <origin rpy="0 0 0" xyz="0 0 0"/>
      <geometry>
        <box size="0.001 0.001 0.001"/>
      </geometry>
    </collision>
  </link>
  <transmission name="br_caster_rotation_trans">
    <type>transmission_interface/SimpleTransmission</type>
    <joint name="br_caster_rotation_joint"/>
    <actuator name="br_caster_rotation_motor">
      <hardwareInterface>EffortJointInterface</hardwareInterface>
      <mechanicalReduction>-79.2380952381</mechanicalReduction>
    </actuator>
  </transmission>
  <joint name="br_caster_r_wheel_joint" type="continuous">
    <axis xyz="0 1 0"/>
    <limit effort="100" velocity="100"/>
    <!-- alpha tested effort and velocity limits -->
    <safety_controller k_velocity="10"/>
    <dynamics damping="0.0" friction="0.0"/>
    <origin rpy="0 0 0" xyz="0 -0.0 0"/>
    <parent link="br_caster_rotation_link"/>
    <child link="br_caster_r_wheel_link"/>
  </joint>
  <link name="br_caster_r_wheel_link">
    <inertial>
      <mass value="0.44036"/>
      <origin xyz="0 0 0"/>
      <inertia ixx="0.012411765597" ixy="-0.000711733678" ixz="0.00050272983" iyy="0.015218160428" iyz="-0.000004273467" izz="0.011763977943"/>
    </inertial>
    <visual>
      <origin rpy="1.57079632679 0 0" xyz="0 0 0"/>
      <geometry>
        <cylinder length="0.034" radius="0.074792"/>
      </geometry>
      <material name="IPA/LightGrey"/>
    </visual>
    <collision>
      <origin rpy="1.57079632679 0 0" xyz="0 0 0"/>
      <!-- rotation because cyl. geom primitive has symmetry axis in +x direction -->
      <geometry>
        <cylinder length="0.034" radius="0.074792"/>
      </geometry>
    </collision>
  </link>
  <gazebo reference="br_caster_r_wheel_link">
    <material value="IPA/LightGrey"/>
  </gazebo>
  <transmission name="br_caster_r_wheel_trans">
    <type>transmission_interface/SimpleTransmission</type>
    <joint name="br_caster_r_wheel_joint"/>
    <actuator name="br_caster_r_wheel_motor">
      <hardwareInterface>EffortJointInterface</hardwareInterface>
      <mechanicalReduction>-79.2380952381</mechanicalReduction>
    </actuator>
  </transmission>
  <gazebo reference="br_caster_rotation_link">
    <material value="IPA/Metal"/>
  </gazebo>
  <gazebo reference="base_link">
    <selfCollide>true</selfCollide>
    <material>IPA/LightGrey</material>
    <sensor name="base_contact_sensor" type="contact">
      <always_on>true</always_on>
      <update_rate>100.0</update_rate>
      <contact>
        <collision>base_link_geom</collision>
        <topic>base_bumper</topic>
      </contact>
      <plugin filename="libgazebo_ros_bumper.so" name="base_gazebo_ros_bumper_controller">
        <frameName>world</frameName>
        <bumperTopicName>base_bumper</bumperTopicName>
      </plugin>
    </sensor>
  </gazebo>
  <gazebo>
    <plugin filename="libgazebo_ros_p3d.so" name="p3d_base_controller">
      <alwaysOn>true</alwaysOn>
      <updateRate>100.0</updateRate>
      <bodyName>base_link</bodyName>
      <topicName>base_pose_ground_truth</topicName>
      <frameName>map</frameName>
      <xyzOffsets>25.7 25.7 0</xyzOffsets>
      <!-- initialize odometry for fake localization-->
      <rpyOffsets>0 0 0</rpyOffsets>
      <gaussianNoise>0.01</gaussianNoise>
    </plugin>
    <canonicalBody>base_footprint</canonicalBody>
  </gazebo>
  <joint name="tray_joint" type="revolute">
    <origin rpy="2.3561 0.0 0.0" xyz="0.2406 0.19 0.732"/>
    <parent link="base_link"/>
    <child link="tray_link"/>
    <axis xyz="0 0 1"/>
    <calibration rising="0.0"/>
    <dynamics damping="5.0" friction="0.5"/>
    <limit effort="100" lower="-3.31612" upper="0.2" velocity="5"/>
  </joint>
  <link name="tray_link">
    <inertial>
      <origin rpy="0 0 0" xyz="0 0 0"/>
      <mass value="0.1"/>
      <inertia ixx="0.01" ixy="0" ixz="0" iyy="0.01" iyz="0" izz="0.01"/>
    </inertial>
    <visual>
      <origin rpy="0 0 0" xyz="0 0 0"/>
      <geometry>
        <mesh filename="package://cob_description/meshes/cob3_tray/tray.stl"/>
      </geometry>
      <material name="IPA/DarkGrey"/>
    </visual>
    <collision>
      <origin rpy="0 0 0" xyz="0 0 0"/>
      <geometry>
        <mesh filename="package://cob_description/meshes/cob3_tray/tray_collision.stl"/>
      </geometry>
    </collision>
  </link>
  <joint name="tray_base_joint" type="fixed">
    <origin rpy="-2.3561 0 0" xyz="0 0 0"/>
    <parent link="tray_link"/>
    <child link="tray_base_link"/>
  </joint>
  <link name="tray_base_link"/>
  <joint name="tray_right_joint" type="fixed">
    <origin rpy="0 0 0" xyz="0.4 -0.3 0.1"/>
    <parent link="tray_base_link"/>
    <child link="tray_right_link"/>
  </joint>
  <link name="tray_right_link"/>
  <joint name="tray_left_joint" type="fixed">
    <origin rpy="0 0 0" xyz="0.4 0.05 0.1"/>
    <parent link="tray_base_link"/>
    <child link="tray_left_link"/>
  </joint>
  <link name="tray_left_link"/>
  <joint name="tray_phidgets_1_joint" type="fixed">
    <axis xyz="0 1 0"/>
    <origin rpy="0 0 -1.57079632679" xyz="-0.275 0 0.02"/>
    <parent link="tray_left_link"/>
    <child link="tray_phidgets_1_link"/>
  </joint>
  <link name="tray_phidgets_1_link"/>
  <gazebo reference="tray_phidgets_1_link">
    <sensor name="tray_phidgets_1" type="ray">
      <always_on>true</always_on>
      <update_rate>10</update_rate>
      <pose>0 0 0 0 0 0</pose>
      <visualize>false</visualize>
      <ray>
        <scan>
          <horizontal>
            <samples>10</samples>
            <resolution>1.0</resolution>
            <min_angle>-0.2</min_angle>
            <max_angle>0.2</max_angle>
          </horizontal>
        </scan>
        <range>
          <min>0.01</min>
          <!-- real value from sensor datasheet is 0.04m -->
          <max>0.4</max>
          <!-- real value from sensor datasheet is 0.30m -->
          <resolution>0.005</resolution>
        </range>
        <noise>
          <type>gaussian</type>
          <mean>0.0</mean>
          <stddev>0.005</stddev>
        </noise>
      </ray>
      <plugin filename="libgazebo_ros_laser.so" name="gazebo_ros_tray_phidgets_1_controller">
        <topicName>/tray_sensors/range_1_sim</topicName>
        <frameName>/tray_phidgets_1_link</frameName>
      </plugin>
    </sensor>
    <material>IPA/LightGrey</material>
  </gazebo>
  <joint name="tray_phidgets_2_joint" type="fixed">
    <axis xyz="0 1 0"/>
    <origin rpy="0 0 -1.57079632679" xyz="-0.2 0 0.02"/>
    <parent link="tray_left_link"/>
    <child link="tray_phidgets_2_link"/>
  </joint>
  <link name="tray_phidgets_2_link"/>
  <gazebo reference="tray_phidgets_2_link">
    <sensor name="tray_phidgets_2" type="ray">
      <always_on>true</always_on>
      <update_rate>10</update_rate>
      <pose>0 0 0 0 0 0</pose>
      <visualize>false</visualize>
      <ray>
        <scan>
          <horizontal>
            <samples>10</samples>
            <resolution>1.0</resolution>
            <min_angle>-0.2</min_angle>
            <max_angle>0.2</max_angle>
          </horizontal>
        </scan>
        <range>
          <min>0.01</min>
          <!-- real value from sensor datasheet is 0.04m -->
          <max>0.4</max>
          <!-- real value from sensor datasheet is 0.30m -->
          <resolution>0.005</resolution>
        </range>
        <noise>
          <type>gaussian</type>
          <mean>0.0</mean>
          <stddev>0.005</stddev>
        </noise>
      </ray>
      <plugin filename="libgazebo_ros_laser.so" name="gazebo_ros_tray_phidgets_2_controller">
        <topicName>/tray_sensors/range_2_sim</topicName>
        <frameName>/tray_phidgets_2_link</frameName>
      </plugin>
    </sensor>
    <material>IPA/LightGrey</material>
  </gazebo>
  <joint name="tray_phidgets_3_joint" type="fixed">
    <axis xyz="0 1 0"/>
    <origin rpy="0 0 -1.57079632679" xyz="-0.125 0 0.02"/>
    <parent link="tray_left_link"/>
    <child link="tray_phidgets_3_link"/>
  </joint>
  <link name="tray_phidgets_3_link"/>
  <gazebo reference="tray_phidgets_3_link">
    <sensor name="tray_phidgets_3" type="ray">
      <always_on>true</always_on>
      <update_rate>10</update_rate>
      <pose>0 0 0 0 0 0</pose>
      <visualize>false</visualize>
      <ray>
        <scan>
          <horizontal>
            <samples>10</samples>
            <resolution>1.0</resolution>
            <min_angle>-0.2</min_angle>
            <max_angle>0.2</max_angle>
          </horizontal>
        </scan>
        <range>
          <min>0.01</min>
          <!-- real value from sensor datasheet is 0.04m -->
          <max>0.4</max>
          <!-- real value from sensor datasheet is 0.30m -->
          <resolution>0.005</resolution>
        </range>
        <noise>
          <type>gaussian</type>
          <mean>0.0</mean>
          <stddev>0.005</stddev>
        </noise>
      </ray>
      <plugin filename="libgazebo_ros_laser.so" name="gazebo_ros_tray_phidgets_3_controller">
        <topicName>/tray_sensors/range_3_sim</topicName>
        <frameName>/tray_phidgets_3_link</frameName>
      </plugin>
    </sensor>
    <material>IPA/LightGrey</material>
  </gazebo>
  <joint name="tray_phidgets_4_joint" type="fixed">
    <axis xyz="0 1 0"/>
    <origin rpy="0 0 -1.57079632679" xyz="-0.05 0 0.02"/>
    <parent link="tray_left_link"/>
    <child link="tray_phidgets_4_link"/>
  </joint>
  <link name="tray_phidgets_4_link"/>
  <gazebo reference="tray_phidgets_4_link">
    <sensor name="tray_phidgets_4" type="ray">
      <always_on>true</always_on>
      <update_rate>10</update_rate>
      <pose>0 0 0 0 0 0</pose>
      <visualize>false</visualize>
      <ray>
        <scan>
          <horizontal>
            <samples>10</samples>
            <resolution>1.0</resolution>
            <min_angle>-0.2</min_angle>
            <max_angle>0.2</max_angle>
          </horizontal>
        </scan>
        <range>
          <min>0.01</min>
          <!-- real value from sensor datasheet is 0.04m -->
          <max>0.4</max>
          <!-- real value from sensor datasheet is 0.30m -->
          <resolution>0.005</resolution>
        </range>
        <noise>
          <type>gaussian</type>
          <mean>0.0</mean>
          <stddev>0.005</stddev>
        </noise>
      </ray>
      <plugin filename="libgazebo_ros_laser.so" name="gazebo_ros_tray_phidgets_4_controller">
        <topicName>/tray_sensors/range_4_sim</topicName>
        <frameName>/tray_phidgets_4_link</frameName>
      </plugin>
    </sensor>
    <material>IPA/LightGrey</material>
  </gazebo>
  <gazebo reference="tray_link">
    <material>IPA/DarkGrey</material>
    <turnGravityOff>false</turnGravityOff>
  </gazebo>
  <transmission name="tray_trans">
    <type>transmission_interface/SimpleTransmission</type>
    <joint name="tray_joint"/>
    <actuator name="tray_motor">
      <hardwareInterface>EffortJointInterface</hardwareInterface>
      <mechanicalReduction>1</mechanicalReduction>
    </actuator>
  </transmission>
  <joint name="torso_base_joint" type="fixed">
    <origin rpy="1.563226442 0.0346163655 0.0107070343" xyz="0.1505153138 0.0 0.8602400721"/>
    <parent link="base_link"/>
    <child link="torso_base_link"/>
  </joint>
  <link name="torso_base_link">
    <inertial>
      <origin rpy="0 0 0" xyz="0 0 0"/>
      <mass value="0.01"/>
      <inertia ixx="1" ixy="0" ixz="0" iyy="1" iyz="0" izz="1"/>
    </inertial>
  </link>
  <joint name="torso_lower_neck_tilt_joint" type="revolute">
    <origin rpy="0 0 0" xyz="0 0 0"/>
    <parent link="torso_base_link"/>
    <child link="torso_lower_neck_tilt_link"/>
    <axis xyz="0 0 1"/>
    <dynamics damping="25.0" friction="10.0"/>
    <calibration rising="0.0"/>
    <limit effort="200.0" lower="-0.25" upper="0.21" velocity="0.5"/>
    <!--safety_controller k_position="20" k_velocity="50" soft_lower_limit="${-0.25 + 0.01}" soft_upper_limit="${0.25 - 0.01}" /-->
  </joint>
  <link name="torso_lower_neck_tilt_link">
    <inertial>
      <origin rpy="0 0 0" xyz="0 0 0"/>
      <mass value="6.209720"/>
      <inertia ixx="0.171118" ixy="0.002544" ixz="-0.000000" iyy="0.083077" iyz="0.000000" izz="0.120948"/>
    </inertial>
    <visual>
      <origin rpy="3.14159265359 0 0" xyz="0 0 0"/>
      <geometry>
        <mesh filename="package://cob_description/meshes/cob3_torso/lower_neck.stl"/>
      </geometry>
      <material name="IPA/LightGrey"/>
    </visual>
    <collision>
      <origin rpy="3.14159265359 0 0" xyz="0 0 0"/>
      <geometry>
        <mesh filename="package://cob_description/meshes/cob3_torso/lower_neck_collision.stl"/>
      </geometry>
    </collision>
  </link>
  <joint name="torso_pan_joint" type="revolute">
    <origin rpy="1.57079632679 0 0" xyz="0 0 0"/>
    <parent link="torso_lower_neck_tilt_link"/>
    <child link="torso_pan_link"/>
    <axis xyz="0 0 1"/>
    <dynamics damping="25.0" friction="10.0"/>
    <calibration rising="0.0"/>
    <limit effort="200.0" lower="-0.12" upper="0.12" velocity="0.5"/>
    <!--safety_controller k_position="20" k_velocity="50" soft_lower_limit="${-0.2 + 0.01}" soft_upper_limit="${0.2 - 0.01}" /-->
  </joint>
  <link name="torso_pan_link">
    <inertial>
      <origin rpy="0 0 0" xyz="0 0 0"/>
      <mass value="1.0"/>
      <inertia ixx="0.200549" ixy="0.001322" ixz="-0.000000" iyy="0.123664" iyz="-0.000000" izz="0.104101"/>
    </inertial>
  </link>
  <joint name="torso_upper_neck_tilt_joint" type="revolute">
    <origin rpy="-1.57079632679 0 0" xyz="0 0 -0.2565"/>
    <parent link="torso_pan_link"/>
    <child link="torso_upper_neck_tilt_link"/>
    <axis xyz="0 0 1"/>
    <dynamics damping="25.0" friction="10.0"/>
    <calibration rising="0.0"/>
    <limit effort="200.0" lower="-0.37" upper="0.37" velocity="0.5"/>
    <!--safety_controller k_position="20" k_velocity="50" soft_lower_limit="${-0.4 + 0.01}" soft_upper_limit="${0.4 - 0.01}" /-->
  </joint>
  <link name="torso_upper_neck_tilt_link">
    <inertial>
      <origin rpy="0 0 0" xyz="0 0 0"/>
      <mass value="6.744238"/>
      <inertia ixx="0.01" ixy="0" ixz="0" iyy="0.01" iyz="0" izz="0.01"/>
    </inertial>
    <visual>
      <origin rpy="3.14159265359 0 0" xyz="0 0 0"/>
      <geometry>
        <mesh filename="package://cob_description/meshes/cob3_torso/upper_neck.stl"/>
      </geometry>
      <material name="IPA/LightGrey"/>
    </visual>
    <collision>
      <origin rpy="3.14159265359 0 0" xyz="0 0 0"/>
      <geometry>
        <!--mesh filename="package://cob_description/meshes/cob3_torso/upper_neck_collision.stl" /-->
        <mesh filename="package://cob_description/meshes/cob3_torso/upper_neck.stl"/>
      </geometry>
    </collision>
  </link>
  <joint name="head_cover_joint" type="fixed">
    <origin rpy="3.14159265359 0 0" xyz="0 0 0"/>
    <parent link="torso_upper_neck_tilt_link"/>
    <child link="head_cover_link"/>
  </joint>
  <link name="head_cover_link">
    <inertial>
      <origin rpy="0 0 0" xyz="0 0 0"/>
      <mass value="0.5"/>
      <inertia ixx="0.01" ixy="0" ixz="0" iyy="0.01" iyz="0" izz="0.01"/>
    </inertial>
    <visual>
      <origin rpy="0 0 0" xyz="0 0 0"/>
      <geometry>
        <mesh filename="package://cob_description/meshes/cob3_torso/head_cover.stl"/>
      </geometry>
      <material name="IPA/Black"/>
    </visual>
    <collision>
      <origin rpy="0 0 0" xyz="0 0 0"/>
      <geometry>
        <mesh filename="package://cob_description/meshes/cob3_torso/head_cover_collision.stl"/>
      </geometry>
    </collision>
  </link>
  <gazebo reference="torso_lower_neck_tilt_link">
    <material>IPA/LightGrey</material>
    <turnGravityOff>false</turnGravityOff>
  </gazebo>
  <gazebo reference="torso_pan_link">
    <material>IPA/LightGrey</material>
    <turnGravityOff>false</turnGravityOff>
  </gazebo>
  <gazebo reference="torso_upper_neck_tilt_link">
    <material>IPA/LightGrey</material>
    <turnGravityOff>false</turnGravityOff>
  </gazebo>
  <gazebo reference="head_cover_link">
    <material>IPA/Black</material>
    <turnGravityOff>false</turnGravityOff>
  </gazebo>
  <transmission name="torso_lower_neck_tilt_trans">
    <type>transmission_interface/SimpleTransmission</type>
    <joint name="torso_lower_neck_tilt_joint"/>
    <actuator name="torso_lower_neck_tilt_motor">
      <hardwareInterface>EffortJointInterface</hardwareInterface>
      <mechanicalReduction>1</mechanicalReduction>
    </actuator>
  </transmission>
  <transmission name="torso_pan_trans">
    <type>transmission_interface/SimpleTransmission</type>
    <joint name="torso_pan_joint"/>
    <actuator name="torso_pan_motor">
      <hardwareInterface>EffortJointInterface</hardwareInterface>
      <mechanicalReduction>1</mechanicalReduction>
    </actuator>
  </transmission>
  <transmission name="torso_upper_neck_tilt_trans">
    <type>transmission_interface/SimpleTransmission</type>
    <joint name="torso_upper_neck_tilt_joint"/>
    <actuator name="torso_upper_neck_tilt_motor">
      <hardwareInterface>EffortJointInterface</hardwareInterface>
      <mechanicalReduction>1</mechanicalReduction>
    </actuator>
  </transmission>
  <joint name="arm_0_joint" type="fixed">
    <origin rpy="-0.1 -0.7554 1.33899265359" xyz="0.04 -0.005 0.83637"/>
    <parent link="base_link"/>
    <child link="arm_0_link"/>
  </joint>
  <link name="arm_0_link">
    <inertial>
      <origin rpy="0 0 0" xyz="0 0 0"/>
      <mass value="1.0"/>
      <inertia ixx="0.01" ixy="0" ixz="0" iyy="0.01" iyz="0" izz="0.01"/>
    </inertial>
    <visual>
      <origin rpy="0 0 0" xyz="0 0 0.004"/>
      <geometry>
        <cylinder length="0.08" radius="0.045"/>
      </geometry>
      <material name="Schunk/Black"/>
    </visual>
    <collision>
      <origin rpy="0 0 0" xyz="0 0 0.005"/>
      <geometry>
        <box size="0.01 0.01 0.01"/>
      </geometry>
    </collision>
  </link>
  <joint name="arm_1_joint" type="revolute">
    <origin rpy="0 -3.14159265359 0" xyz="0 0 0.15"/>
    <parent link="arm_0_link"/>
    <child link="arm_1_link"/>
    <axis xyz="0 0 1"/>
    <calibration rising="-0.296164920771"/>
    <dynamics damping="10"/>
    <limit effort="370" lower="-3.438" upper="2.846" velocity="2.0"/>
    <safety_controller k_position="20" k_velocity="50" soft_lower_limit="-3.428" soft_upper_limit="2.836"/>
  </joint>
  <link name="arm_1_link">
    <inertial>
      <origin rpy="0 0 0" xyz="0 0 0"/>
      <!--mass value="5.9907"/-->
      <mass value="2.0"/>
      <inertia ixx="0.01" ixy="0" ixz="0" iyy="0.01" iyz="0" izz="0.01"/>
    </inertial>
    <visual>
      <origin rpy="0 0 3.14159265359" xyz="0 0 -0.15"/>
      <geometry>
        <mesh filename="package://schunk_description/meshes/lwa4d/arm_1_link.stl"/>
      </geometry>
      <material name="Schunk/LightGrey"/>
    </visual>
    <collision>
      <origin rpy="0 0 3.14159265359" xyz="0 0 -0.15"/>
      <geometry>
        <mesh filename="package://schunk_description/meshes/lwa4d/arm_1_link.stl"/>
      </geometry>
    </collision>
  </link>
  <joint name="arm_2_joint" type="revolute">
    <origin rpy="-1.57079632679 0 0" xyz="0 0 -0.15"/>
    <parent link="arm_1_link"/>
    <child link="arm_2_link"/>
    <axis xyz="0 0 1"/>
    <calibration rising="0.0"/>
    <dynamics damping="10"/>
    <limit effort="370" lower="-2.14675498" upper="2.14675498" velocity="2.0"/>
    <safety_controller k_position="20" k_velocity="50" soft_lower_limit="-2.13675498" soft_upper_limit="2.13675498"/>
  </joint>
  <link name="arm_2_link">
    <inertial>
      <origin rpy="0 0 0" xyz="0 0 0"/>
      <mass value="2.0"/>
      <inertia ixx="0.03" ixy="0" ixz="0" iyy="0.03" iyz="0" izz="0.03"/>
    </inertial>
    <visual>
      <origin rpy="0 0 3.14159265359" xyz="0 0 0"/>
      <geometry>
        <mesh filename="package://schunk_description/meshes/lwa4d/arm_2_link.stl"/>
      </geometry>
      <material name="Schunk/Black"/>
    </visual>
    <collision>
      <origin rpy="0 0 3.14159265359" xyz="0 0 0"/>
      <geometry>
        <mesh filename="package://schunk_description/meshes/lwa4d/arm_2_link.stl"/>
      </geometry>
    </collision>
  </link>
  <joint name="arm_3_joint" type="revolute">
    <origin rpy="1.57079632679 0 0" xyz="0 0 0"/>
    <parent link="arm_2_link"/>
    <child link="arm_3_link"/>
    <axis xyz="0 0 1"/>
    <calibration rising="0.0"/>
    <dynamics damping="5"/>
    <limit effort="176" lower="-3.141592654" upper="3.141592654" velocity="2.0"/>
    <safety_controller k_position="20" k_velocity="25" soft_lower_limit="-3.131592654" soft_upper_limit="3.131592654"/>
  </joint>
  <link name="arm_3_link">
    <inertial>
      <origin rpy="0 0 0" xyz="0 0 0"/>
      <mass value="2.0"/>
      <inertia ixx="0.03" ixy="0" ixz="0" iyy="0.03" iyz="0" izz="0.03"/>
    </inertial>
    <visual>
      <origin rpy="0 0 3.14159265359" xyz="0 0 -0.328"/>
      <geometry>
        <mesh filename="package://schunk_description/meshes/lwa4d/arm_3_link.stl"/>
      </geometry>
      <material name="Schunk/LightGrey"/>
    </visual>
    <collision>
      <origin rpy="0 0 3.14159265359" xyz="0 0 -0.328"/>
      <geometry>
        <mesh filename="package://schunk_description/meshes/lwa4d/arm_3_link.stl"/>
      </geometry>
    </collision>
  </link>
  <joint name="arm_4_joint" type="revolute">
    <origin rpy="-1.57079632679 0 0" xyz="0 0 -0.328"/>
    <parent link="arm_3_link"/>
    <child link="arm_4_link"/>
    <axis xyz="0 0 1"/>
    <calibration rising="0.0"/>
    <dynamics damping="5"/>
    <limit effort="176" lower="-2.181661565" upper="2.181661565" velocity="2.0"/>
    <safety_controller k_position="20" k_velocity="25" soft_lower_limit="-2.171661565" soft_upper_limit="2.171661565"/>
  </joint>
  <link name="arm_4_link">
    <inertial>
      <origin rpy="0 0 0" xyz="0 0 0"/>
      <mass value="2.0"/>
      <inertia ixx="0.03" ixy="0" ixz="0" iyy="0.03" iyz="0" izz="0.03"/>
    </inertial>
    <visual>
      <origin rpy="0 0 3.14159265359" xyz="0 0 0"/>
      <geometry>
        <mesh filename="package://schunk_description/meshes/lwa4d/arm_4_link.stl"/>
      </geometry>
      <material name="Schunk/Black"/>
    </visual>
    <collision>
      <origin rpy="0 0 3.14159265359" xyz="0 0 0"/>
      <geometry>
        <mesh filename="package://schunk_description/meshes/lwa4d/arm_4_link.stl"/>
      </geometry>
    </collision>
  </link>
  <joint name="arm_5_joint" type="revolute">
    <origin rpy="1.57079632679 0 0" xyz="0 0 0"/>
    <parent link="arm_4_link"/>
    <child link="arm_5_link"/>
    <axis xyz="0 0 1"/>
    <calibration rising="0.0"/>
    <dynamics damping="5"/>
    <limit effort="41.6" lower="-3.141592654" upper="3.141592654" velocity="2.0"/>
    <safety_controller k_position="20" k_velocity="25" soft_lower_limit="-3.131592654" soft_upper_limit="3.131592654"/>
  </joint>
  <link name="arm_5_link">
    <inertial>
      <origin rpy="0 0 0" xyz="0 0 0"/>
      <mass value="2.313272"/>
      <inertia ixx="0.03" ixy="0" ixz="0" iyy="0.03" iyz="0" izz="0.03"/>
    </inertial>
    <visual>
      <origin rpy="0 0 3.14159265359" xyz="0 0 -0.323"/>
      <geometry>
        <mesh filename="package://schunk_description/meshes/lwa4d/arm_5_link.stl"/>
      </geometry>
      <material name="Schunk/LightGrey"/>
    </visual>
    <collision>
      <origin rpy="0 0 3.14159265359" xyz="0 0 -0.323"/>
      <geometry>
        <mesh filename="package://schunk_description/meshes/lwa4d/arm_5_link.stl"/>
      </geometry>
    </collision>
  </link>
  <joint name="arm_6_joint" type="revolute">
    <origin rpy="-1.57079632679 0 0" xyz="0 0 -0.323"/>
    <parent link="arm_5_link"/>
    <child link="arm_6_link"/>
    <axis xyz="0 0 1"/>
    <calibration rising="0.0"/>
    <dynamics damping="5"/>
    <limit effort="20.1" lower="-2.0" upper="2.0" velocity="2.0"/>
    <safety_controller k_position="20" k_velocity="25" soft_lower_limit="-2.957059728" soft_upper_limit="2.957059728"/>
  </joint>
  <link name="arm_6_link">
    <inertial>
      <origin rpy="0 0 0" xyz="0 0 0"/>
      <mass value="2.057856"/>
      <inertia ixx="0.01" ixy="0" ixz="0" iyy="0.01" iyz="0" izz="0.01"/>
    </inertial>
    <visual>
      <origin rpy="0 3.14159265359 0" xyz="0 0 0"/>
      <geometry>
        <mesh filename="package://schunk_description/meshes/lwa4d/arm_6_link.stl"/>
      </geometry>
      <material name="Schunk/Black"/>
    </visual>
    <collision>
      <origin rpy="0 3.14159265359 0" xyz="0 0 0"/>
      <geometry>
        <mesh filename="package://schunk_description/meshes/lwa4d/arm_6_link.stl"/>
      </geometry>
    </collision>
  </link>
  <joint name="arm_7_joint" type="revolute">
    <origin rpy="-1.57079632679 0 0" xyz="0 0 0"/>
    <parent link="arm_6_link"/>
    <child link="arm_7_link"/>
    <axis xyz="0 0 1"/>
    <calibration rising="0.0"/>
    <dynamics damping="5"/>
    <limit effort="9.6" lower="-2.967059728" upper="2.967059728" velocity="2.0"/>
    <safety_controller k_position="20" k_velocity="25" soft_lower_limit="-2.957059728" soft_upper_limit="2.957059728"/>
  </joint>
  <link name="arm_7_link">
    <inertial>
      <origin rpy="0 0 0" xyz="0 0 0"/>
      <mass value="1.120198"/>
      <inertia ixx="0.01" ixy="0" ixz="0" iyy="0.01" iyz="0" izz="0.01"/>
    </inertial>
    <visual>
      <origin rpy="0 0 0" xyz="0 0 0"/>
      <geometry>
        <mesh filename="package://schunk_description/meshes/lwa4d/arm_7_link.stl"/>
      </geometry>
      <material name="Schunk/LightGrey"/>
    </visual>
    <collision>
      <origin rpy="0 0 0" xyz="0 0 0"/>
      <geometry>
        <mesh filename="package://schunk_description/meshes/lwa4d/arm_7_link.stl"/>
      </geometry>
    </collision>
  </link>
  <gazebo reference="arm_0_link">
    <material value="Schunk/DarkGolden"/>
    <turnGravityOff>false</turnGravityOff>
  </gazebo>
  <gazebo reference="arm_1_link">
    <material value="Schunk/DarkGolden"/>
    <turnGravityOff>false</turnGravityOff>
  </gazebo>
  <gazebo reference="arm_2_link">
    <material value="Schunk/DarkGolden"/>
    <turnGravityOff>false</turnGravityOff>
  </gazebo>
  <gazebo reference="arm_3_link">
    <material value="Schunk/DarkGolden"/>
    <turnGravityOff>false</turnGravityOff>
  </gazebo>
  <gazebo reference="arm_4_link">
    <material value="Schunk/DarkGolden"/>
    <turnGravityOff>false</turnGravityOff>
  </gazebo>
  <gazebo reference="arm_5_link">
    <material value="Schunk/DarkGolden"/>
    <turnGravityOff>false</turnGravityOff>
  </gazebo>
  <gazebo reference="arm_6_link">
    <material value="Schunk/DarkGolden"/>
    <turnGravityOff>false</turnGravityOff>
  </gazebo>
  <gazebo reference="arm_7_link">
    <material value="Schunk/DarkGolden"/>
    <turnGravityOff>false</turnGravityOff>
  </gazebo>
  <transmission name="arm_1_trans">
    <type>transmission_interface/SimpleTransmission</type>
    <joint name="arm_1_joint"/>
    <actuator name="arm_1_motor">
      <hardwareInterface>EffortJointInterface</hardwareInterface>
      <mechanicalReduction>1</mechanicalReduction>
    </actuator>
  </transmission>
  <transmission name="arm_2_trans">
    <type>transmission_interface/SimpleTransmission</type>
    <joint name="arm_2_joint"/>
    <actuator name="arm_2_motor">
      <hardwareInterface>EffortJointInterface</hardwareInterface>
      <mechanicalReduction>1</mechanicalReduction>
    </actuator>
  </transmission>
  <transmission name="arm_3_trans">
    <type>transmission_interface/SimpleTransmission</type>
    <joint name="arm_3_joint"/>
    <actuator name="arm_3_motor">
      <hardwareInterface>EffortJointInterface</hardwareInterface>
      <mechanicalReduction>1</mechanicalReduction>
    </actuator>
  </transmission>
  <transmission name="arm_4_trans">
    <type>transmission_interface/SimpleTransmission</type>
    <joint name="arm_4_joint"/>
    <actuator name="arm_4_motor">
      <hardwareInterface>EffortJointInterface</hardwareInterface>
      <mechanicalReduction>1</mechanicalReduction>
    </actuator>
  </transmission>
  <transmission name="arm_5_trans">
    <type>transmission_interface/SimpleTransmission</type>
    <joint name="arm_5_joint"/>
    <actuator name="arm_5_motor">
      <hardwareInterface>EffortJointInterface</hardwareInterface>
      <mechanicalReduction>1</mechanicalReduction>
    </actuator>
  </transmission>
  <transmission name="arm_6_trans">
    <type>transmission_interface/SimpleTransmission</type>
    <joint name="arm_6_joint"/>
    <actuator name="arm_6_motor">
      <hardwareInterface>EffortJointInterface</hardwareInterface>
      <mechanicalReduction>1</mechanicalReduction>
    </actuator>
  </transmission>
  <transmission name="arm_7_trans">
    <type>transmission_interface/SimpleTransmission</type>
    <joint name="arm_7_joint"/>
    <actuator name="arm_7_motor">
      <hardwareInterface>EffortJointInterface</hardwareInterface>
      <mechanicalReduction>1</mechanicalReduction>
    </actuator>
  </transmission>
  <joint name="head_base_joint" type="fixed">
    <origin rpy="0.0 0.0 0.0" xyz="0.0 0.173 0.0"/>
    <parent link="torso_upper_neck_tilt_link"/>
    <child link="head_base_link"/>
  </joint>
  <link name="head_base_link">
    <inertial>
      <origin rpy="0 0 0" xyz="0 0 0"/>
      <mass value="0.5"/>
      <inertia ixx="0.01" ixy="0" ixz="0" iyy="0.01" iyz="0" izz="0.01"/>
    </inertial>
  </link>
  <joint name="head_axis_joint" type="revolute">
    <parent link="head_base_link"/>
    <origin rpy="0 0 0" xyz="0 0 0"/>
    <child link="head_axis_link"/>
    <axis xyz="0 0 1"/>
    <dynamics damping="0.1"/>
    <calibration rising="0.1"/>
    <limit effort="100" lower="-3.2" upper="0.1" velocity="1.4"/>
  </joint>
  <link name="head_axis_link">
    <inertial>
      <origin rpy="0 0 0" xyz="0 0 0"/>
      <mass value="0.1"/>
      <inertia ixx="0.0001" ixy="0" ixz="0" iyy="0.0001" iyz="0" izz="0.0001"/>
    </inertial>
    <visual>
      <origin rpy="0 0 0" xyz="0 0 0"/>
      <geometry>
        <box size="0.01 0.01 0.01"/>
      </geometry>
      <material name="IPA/Black"/>
    </visual>
    <collision>
      <origin rpy="0 0 0" xyz="0 0 0"/>
      <geometry>
        <box size="0.01 0.01 0.01"/>
      </geometry>
    </collision>
  </link>
  <joint name="head_cam_reference_joint" type="fixed">
    <origin rpy="0.0 -1.5563904314 0.0" xyz="-0.05 -0.02 -0.07"/>
    <parent link="head_axis_link"/>
    <child link="head_cam_reference_link"/>
  </joint>
  <link name="head_cam_reference_link">
    <inertial>
      <origin rpy="0 0 0" xyz="0 0 0"/>
      <mass value="0.5"/>
      <inertia ixx="0.01" ixy="0" ixz="0" iyy="0.01" iyz="0" izz="0.01"/>
    </inertial>
  </link>
  <joint name="cam3d_joint" type="fixed">
    <origin rpy="0.0 0.0 0.0" xyz="0.06 -0.03 0.0"/>
    <parent link="head_cam_reference_link"/>
    <child link="cam3d_link"/>
  </joint>
  <link name="cam3d_link">
    <inertial>
      <mass value="0.3"/>
      <origin rpy="0 0 0" xyz="0 0 0"/>
      <inertia ixx="9.312496275e-05" ixy="0.0" ixz="0.0" iyy="0.000872499651" iyz="0.0" izz="0.00084062466375"/>
    </inertial>
    <visual>
      <origin rpy="0 0 0" xyz="0 0 -0.03"/>
      <geometry>
        <box size="0.02 0.02 0.02"/>
      </geometry>
      <material name="IPA/LightGrey"/>
    </visual>
    <collision>
      <origin rpy="0 0 0" xyz="0 0 -0.03"/>
      <geometry>
        <box size="0.02 0.02 0.02"/>
      </geometry>
    </collision>
  </link>
  <joint name="cam3d_frame_joint" type="fixed">
    <origin rpy="1.57079632679 -1.57079632679 0" xyz="0 0 0"/>
    <parent link="cam3d_link"/>
    <child link="cam3d_frame"/>
  </joint>
  <link name="cam3d_frame"/>
  <gazebo reference="cam3d_frame">
    <sensor name="cam3d_frame_sensor" type="depth">
      <always_on>true</always_on>
      <update_rate>20.0</update_rate>
      <camera>
        <horizontal_fov>1.08210413624</horizontal_fov>
        <image>
          <format>R8G8B8</format>
          <width>640</width>
          <height>480</height>
        </image>
        <clip>
          <near>0.1</near>
          <far>100</far>
        </clip>
        <noise>
          <type>gaussian</type>
          <mean>0.0</mean>
          <stddev>0.0</stddev>
        </noise>
      </camera>
      <plugin filename="libgazebo_ros_openni_kinect.so" name="cam3d_controller">
        <updateRate>20.0</updateRate>
        <cameraName>cam3d</cameraName>
        <frameName>cam3d_link</frameName>
        <imageTopicName>rgb/image_raw</imageTopicName>
        <depthImageTopicName>depth/image_raw</depthImageTopicName>
        <pointCloudTopicName>depth_registered/points</pointCloudTopicName>
        <cameraInfoTopicName>rgb/camera_info</cameraInfoTopicName>
        <depthImageCameraInfoTopicName>depth_registered/camera_info</depthImageCameraInfoTopicName>
        <pointCloudCutoff>0.5</pointCloudCutoff>
        <baseline>0.2</baseline>
        <hackBaseline>0.0</hackBaseline>
        <distortionK1>0.0</distortionK1>
        <distortionK2>0.0</distortionK2>
        <distortionK3>0.0</distortionK3>
        <distortionT1>0.0</distortionT1>
        <distortionT2>0.0</distortionT2>
        <CxPrime>0.0</CxPrime>
        <Cx>0.0</Cx>
        <Cy>0.0</Cy>
        <focalLength>0.0</focalLength>
      </plugin>
    </sensor>
    <material>IPA/LightGrey</material>
  </gazebo>
  <gazebo reference="head_axis_link">
    <material>IPA/LightGrey</material>
    <turnGravityOff>false</turnGravityOff>
  </gazebo>
  <transmission name="head_axis_trans">
    <type>transmission_interface/SimpleTransmission</type>
    <joint name="head_axis_joint"/>
    <actuator name="head_axis_motor">
      <hardwareInterface>EffortJointInterface</hardwareInterface>
      <mechanicalReduction>1</mechanicalReduction>
    </actuator>
  </transmission>
  <joint name="lookat_base_joint" type="fixed">
    <origin rpy="0.0 0.0 0.0" xyz="0.0 0.173 0.0"/>
    <parent link="torso_upper_neck_tilt_link"/>
    <child link="lookat_base_link"/>
  </joint>
  <link name="lookat_base_link"/>
  <joint name="lookat_lin_joint" type="prismatic">
    <origin rpy="0 0 0" xyz="0 0 0"/>
    <parent link="lookat_base_link"/>
    <child link="lookat_x_link"/>
    <axis xyz="-1 0 0"/>
    <!--axis xyz="-1 0 0" /-->
    <dynamics damping="5.0" friction="0.5"/>
    <limit effort="100" lower="-5.0" upper="5.0" velocity="1"/>
  </joint>
  <link name="lookat_x_link"/>
  <joint name="lookat_x_joint" type="revolute">
    <origin rpy="0 0 0" xyz="0 0 0"/>
    <parent link="lookat_x_link"/>
    <child link="lookat_y_link"/>
    <axis xyz="1 0 0"/>
    <dynamics damping="5.0" friction="0.5"/>
    <limit effort="100" lower="-3.14159265359" upper="3.14159265359" velocity="1"/>
  </joint>
  <link name="lookat_y_link"/>
  <joint name="lookat_y_joint" type="revolute">
    <origin rpy="0 0 0" xyz="0 0 0"/>
    <parent link="lookat_y_link"/>
    <child link="lookat_z_link"/>
    <axis xyz="0 1 0"/>
    <dynamics damping="5.0" friction="0.5"/>
    <limit effort="100" lower="-3.14159265359" upper="3.14159265359" velocity="1"/>
  </joint>
  <link name="lookat_z_link"/>
  <joint name="lookat_z_joint" type="revolute">
    <origin rpy="0 0 0" xyz="0 0 0"/>
    <parent link="lookat_z_link"/>
    <child link="lookat_focus_frame"/>
    <axis xyz="0 0 1"/>
    <dynamics damping="5.0" friction="0.5"/>
    <limit effort="100" lower="-3.14159265359" upper="3.14159265359" velocity="1"/>
  </joint>
  <link name="lookat_focus_frame">
    <!--
      <visual>
        <origin xyz="0 0 0" rpy="0 0 0" />
        <geometry>
          <box size="0.05 0.05 0.2"/>
        </geometry>
        <material name="IPA/Black" />
      </visual>
-->
  </link>
  <joint name="pg70_gripper_joint" type="fixed">
    <parent link="arm_7_link"/>
    <child link="pg70_gripper_link"/>
    <origin rpy="0.0 0.0 0.0" xyz="0.0 0.0 0.075"/>
  </joint>
  <link name="pg70_gripper_link">
    <inertial>
      <origin rpy="0 0 0" xyz="0 0 0"/>
      <mass value="1"/>
      <inertia ixx="0.01" ixy="0" ixz="0" iyy="0.01" iyz="0" izz="0.01"/>
    </inertial>
    <visual>
      <geometry>
        <mesh filename="package://schunk_description/meshes/pg70/pg70.dae"/>
      </geometry>
      <material name="blue">
        <color rgba="0 0 1 1"/>
      </material>
    </visual>
    <collision>
      <geometry>
        <mesh filename="package://schunk_description/meshes/pg70/pg70.dae"/>
      </geometry>
      <material name="blue">
        <color rgba="0 0 1 1"/>
      </material>
    </collision>
  </link>
  <joint name="pg70_finger_left_joint" type="prismatic">
    <parent link="pg70_gripper_link"/>
    <child link="pg70_finger_left_link"/>
    <limit effort="100" lower="-0.008" upper="0.026" velocity="2.0"/>
    <calibration rising="0.0"/>
    <origin rpy="0 0 0" xyz="0 0.0105 0.0619"/>
    <axis xyz="0 1 0"/>
  </joint>
  <link name="pg70_finger_left_link">
    <inertial>
      <origin rpy="0 0 0" xyz="0 0 0"/>
      <mass value="1"/>
      <inertia ixx="0.01" ixy="0" ixz="0" iyy="0.01" iyz="0" izz="0.01"/>
    </inertial>
    <visual>
      <origin rpy="0 0 0" xyz="0 0 0.05"/>
      <geometry>
        <box size="0.03 0.02 0.10"/>
      </geometry>
      <material name="black">
        <color rgba="0 0 0 1"/>
      </material>
    </visual>
    <collision>
      <origin rpy="0 0 0" xyz="0 0 0.05"/>
      <geometry>
        <box size="0.03 0.02 0.10"/>
      </geometry>
      <material name="black">
        <color rgba="0 0 0 1"/>
      </material>
    </collision>
  </link>
  <joint name="pg70_finger_right_joint" type="prismatic">
    <mimic joint="pg70_finger_left_joint" multiplier="1" offset="0"/>
    <parent link="pg70_gripper_link"/>
    <child link="pg70_finger_right_link"/>
    <limit effort="100" lower="-0.008" upper="0.026" velocity="2.0"/>
    <calibration rising="0.0"/>
    <origin rpy="-0 0 0" xyz="0 -0.0105 0.0619"/>
    <axis xyz="0 -1 0"/>
  </joint>
  <link name="pg70_finger_right_link">
    <inertial>
      <origin rpy="0 0 0" xyz="0 0 0"/>
      <mass value="1"/>
      <inertia ixx="0.01" ixy="0" ixz="0" iyy="0.01" iyz="0" izz="0.01"/>
    </inertial>
    <visual>
      <origin rpy="0 0 0" xyz="0 0 0.05"/>
      <geometry>
        <box size="0.03 0.02 0.10"/>
      </geometry>
      <material name="black">
        <color rgba="0 0 0 1"/>
      </material>
    </visual>
    <collision>
      <origin rpy="0 0 0" xyz="0 0 0.05"/>
      <geometry>
        <box size="0.03 0.02 0.10"/>
      </geometry>
      <material name="black">
        <color rgba="0 0 0 1"/>
      </material>
    </collision>
  </link>
  <gazebo reference="pg70_palm_link">
    <material>Schunk/LightGrey</material>
    <turnGravityOff>false</turnGravityOff>
  </gazebo>
  <gazebo reference="pg70_finger_left_link">
    <material>Schunk/LightGrey</material>
    <turnGravityOff>false</turnGravityOff>
  </gazebo>
  <gazebo reference="pg70_finger_right_link">
    <material>Schunk/LightGrey</material>
    <turnGravityOff>false</turnGravityOff>
  </gazebo>
  <transmission name="pg70_finger_trans">
    <type>transmission_interface/SimpleTransmission</type>
    <joint name="pg70_finger_left_joint"/>
    <actuator name="pg70_finger_motor">
      <hardwareInterface>EffortJointInterface</hardwareInterface>
      <mechanicalReduction>1</mechanicalReduction>
    </actuator>
  </transmission>
  <transmission name="pg70_finger_mimic_trans">
    <type>transmission_interface/SimpleTransmission</type>
    <joint name="pg70_finger_right_joint"/>
    <actuator name="pg70_finger_mimic_motor">
      <hardwareInterface>EffortJointInterface</hardwareInterface>
      <mechanicalReduction>1</mechanicalReduction>
    </actuator>
  </transmission>
</robot>

